Workbook

Sheet Overview
A1: Semesters | B1: Term | I1: Cumulative
A2: Transfer/Vertical 23 crds | B2: Term Crds | C2: Term Pts | D2: Term GPA | E2: Major Crds | F2: Major Pts | G2: Major GPA | I2: Sub Crds | J2: Total Pts | K2: Total GPA | L2: Major Crds | M2: Major Pts | N2: Major GPA | O2: Total Crds
A3: Fall 2017 | B3: =SUMIF(Semesters!$A$2:$A$45,Overview!A3,Semesters!$C$2:$C$45) -> 13 | C3: =SUMIF(Semesters!$A$2:$A$45,Overview!A3,Semesters!$E$2:$E$45) -> 49.4 | D3: =C3/B3 -> 3.8 | E3: =SUM(Semesters!C3:C6) -> 9 | F3: =SUMIF(Semesters!$A$2:$A$45,Overview!A3,Semesters!$H$2:$H$45) -> 36 | G3: =F3/E3 -> 4 | I3: =B3 -> 13 | J3: =C3 -> 49.4 | K3: =J3/(I3) -> 3.8 | L3: =E3 -> 9 | M3: =F3 -> 36 | N3: =M3/(L3) -> 4 | O3: =23 + I3 -> 36
A4: Spring 2018 | B4: =SUMIF(Semesters!$A$2:$A$45,Overview!A4,Semesters!$C$2:$C$45) -> 14 | C4: =SUMIF(Semesters!$A$2:$A$45,Overview!A4,Semesters!$E$2:$E$45) -> 56 | D4: =C4/B4 -> 4 | E4: =SUM(Semesters!C9:C11) -> 9 | F4: =SUMIF(Semesters!$A$2:$A$45,Overview!A4,Semesters!$H$2:$H$45) -> 36 | G4: =F4/E4 -> 4 | I4: =B4+I3 -> 27 | J4: =J3+C4 -> 105.4 | K4: =J4/(I4) -> 3.9037037 | L4: =E4+L3 -> 18 | M4: =M3+F4 -> 72 | N4: =M4/(L4) -> 4 | O4: =I4+23 -> 50
A5: Summer 2018 | B5: =SUMIF(Semesters!$A$2:$A$45,Overview!A5,Semesters!$C$2:$C$45) -> 2 | C5: =SUMIF(Semesters!$A$2:$A$45,Overview!A5,Semesters!$E$2:$E$45) -> 8 | D5: =C5/B5 -> 4 | E5: =0 -> 0 | F5: =SUMIF(Semesters!$A$2:$A$45,Overview!A5,Semesters!$H$2:$H$45) -> 0 | G5: 0 | I5: =B5+I4 -> 29 | J5: =J4+C5 -> 113.4 | K5: =J5/(I5) -> 3.9103448 | L5: =E5+L4 -> 18 | M5: =M4+F5 -> 72 | N5: =M5/(L5) -> 4 | O5: =I5+23 -> 52
A6: Fall 2018 | B6: =SUMIF(Semesters!$A$2:$A$45,Overview!A6,Semesters!$C$2:$C$45) -> 14.5 | C6: =SUMIF(Semesters!$A$2:$A$45,Overview!A6,Semesters!$E$2:$E$45) -> 56.2 | D6: =C6/B6 -> 3.8758621 | E6: =SUM(Semesters!C14:C15)+Semesters!C17 -> 11 | F6: =SUMIF(Semesters!$A$2:$A$45,Overview!A6,Semesters!$H$2:$H$45) -> 42.2 | G6: =F6/E6 -> 3.8363636 | I6: =B6+I5 -> 43.5 | J6: =J5+C6 -> 169.6 | K6: =J6/(I6) -> 3.8988506 | L6: =E6+L5 -> 29 | M6: =M5+F6 -> 114.2 | N6: =M6/(L6) -> 3.937931 | O6: =I6+23 -> 66.5
A7: Winter 2019 | B7: =SUMIF(Semesters!$A$2:$A$45,Overview!A7,Semesters!$C$2:$C$45) -> 12.5 | C7: =SUMIF(Semesters!$A$2:$A$45,Overview!A7,Semesters!$E$2:$E$45) -> 43.7 | D7: =C7/B7 -> 3.496 | E7: =Semesters!C20+SUM(Semesters!C22:C23) -> 9 | F7: =SUMIF(Semesters!$A$2:$A$45,Overview!A7,Semesters!$H$2:$H$45) -> 30 | G7: =F7/E7 -> 3.3333333 | I7: =B7+I6 -> 56 | J7: =J6+C7 -> 213.3 | K7: =J7/(I7) -> 3.8089286 | L7: =E7+L6 -> 38 | M7: =M6+F7 -> 144.2 | N7: =M7/(L7) -> 3.7947368 | O7: =I7+23 -> 79
A8: Spring 2019 | B8: =SUMIF(Semesters!$A$2:$A$45,Overview!A8,Semesters!$C$2:$C$45) -> 10 | C8: =SUMIF(Semesters!$A$2:$A$45,Overview!A8,Semesters!$E$2:$E$45) -> 35.2 | D8: =C8/B8 -> 3.52 | E8: =B8 -> 10 | F8: =SUMIF(Semesters!$A$2:$A$45,Overview!A8,Semesters!$H$2:$H$45) -> 35.2 | G8: =F8/E8 -> 3.52 | I8: =B8+I7 -> 66 | J8: =J7+C8 -> 248.5 | K8: =J8/(I8) -> 3.7651515 | L8: =E8+L7 -> 48 | M8: =M7+F8 -> 179.4 | N8: =M8/(L8) -> 3.7375 | O8: =I8+23 -> 89
A9: Summer 2019 | B9: =SUMIF(Semesters!$A$2:$A$45,Overview!A9,Semesters!$C$2:$C$45) -> 3 | C9: =SUMIF(Semesters!$A$2:$A$45,Overview!A9,Semesters!$E$2:$E$45) -> 10.2 | D9: =C9/B9 -> 3.4 | E9: 0 | F9: =SUMIF(Semesters!$A$2:$A$45,Overview!A9,Semesters!$H$2:$H$45) -> 0 | G9: 0 | I9: =B9+I8 -> 69 | J9: =J8+C9 -> 258.7 | K9: =J9/(I9) -> 3.7492754 | L9: =E9+L8 -> 48 | M9: =M8+F9 -> 179.4 | N9: =M9/(L9) -> 3.7375 | O9: =I9+23 -> 92
A10: Fall 2019 | B10: =SUMIF(Semesters!$A$2:$A$45,Overview!A10,Semesters!$C$2:$C$45) -> 13 | C10: =SUMIF(Semesters!$A$2:$A$45,Overview!A10,Semesters!$E$2:$E$45) -> 37 | D10: =C10/B10 -> 2.8461538 | E10: =SUM(Semesters!C34:C36) -> 9 | F10: =SUMIF(Semesters!$A$2:$A$45,Overview!A10,Semesters!$H$2:$H$45) -> 22.2 | G10: =F10/E10 -> 2.4666667 | I10: =B10+I9 -> 82 | J10: =J9+C10 -> 295.7 | K10: =J10/(I10) -> 3.6060976 | L10: =E10+L9 -> 57 | M10: =M9+F10 -> 201.6 | N10: =M10/(L10) -> 3.5368421 | O10: =I10+23 -> 105
A11: Winter 2020 | B11: =SUMIF(Semesters!$A$2:$A$45,Overview!A11,Semesters!$C$2:$C$45) -> 12 | C11: =SUMIF(Semesters!$A$2:$A$45,Overview!A11,Semesters!$E$2:$E$45) -> 45.3 | D11: =C11/B11 -> 3.775 | E11: =SUM(Semesters!C38:C40) -> 9 | F11: =SUMIF(Semesters!$A$2:$A$45,Overview!A11,Semesters!$H$2:$H$45) -> 34.2 | G11: =F11/E11 -> 3.8 | I11: =B11+I10 -> 94 | J11: =J10+C11 -> 341 | K11: =J11/(I11) -> 3.6276596 | L11: =E11+L10 -> 66 | M11: =M10+F11 -> 235.8 | N11: =M11/(L11) -> 3.5727273 | O11: =I11+23 -> 117
A12: Spring 2020 | B12: =SUMIF(Semesters!$A$2:$A$45,Overview!A12,Semesters!$C$2:$C$45) -> 8 | C12: =SUMIF(Semesters!$A$2:$A$45,Overview!A12,Semesters!$E$2:$E$45) -> 32 | D12: =C12/B12 -> 4 | E12: =B12 -> 8 | F12: =SUMIF(Semesters!$A$2:$A$45,Overview!A12,Semesters!$H$2:$H$45) -> 32 | G12: =F12/E12 -> 4 | I12: =B12+I11 -> 102 | J12: =J11+C12 -> 373 | K12: =J12/(I12) -> 3.6568627 | L12: =E12+L11 -> 74 | M12: =M11+F12 -> 267.8 | N12: =M12/(L12) -> 3.6189189 | O12: =I12+23 -> 125
A13: Fall 2020 | B13: =SUMIF(Semesters!$A$2:$A$498,Overview!A13,Semesters!$C$2:$C$498) -> 6 | C13: =SUMIF(Semesters!$A$2:$A$498,Overview!A13,Semesters!$E$2:$E$498) -> 20.4 | D13: =C13/B13 -> 3.4 | E13: =B13 -> 6 | F13: =SUMIF(Semesters!$A$2:$A$498,Overview!A13,Semesters!$H$2:$H$498) -> 20.4 | G13: =F13/E13 -> 3.4 | I13: =B13+I12 -> 108 | J13: =J12+C13 -> 393.4 | K13: =J13/(I13) -> 3.6425926 | L13: =E13+L12 -> 80 | M13: =M12+F13 -> 288.2 | N13: =M13/(L13) -> 3.6025 | O13: =I13+23 -> 131

Sheet Core
A1: Software Engineering (BS)
A2: Academic Core | D2: =SUM(D4:D19) -> 39 | F2: Major Core | P2: =SUM(J4:J15)+SUM(P4:P18) -> 69
A3: P | B3: Code | C3: Name | D3: Crds | F3: P | G3: New | H3: Old | I3: Name | J3: Crds | L3: P | M3: New | N3: Old | O3: Name | P3: Crds
A4: X | B4: REL 200 | C4: The Eternal Family | D4: 2 | F4: X | G4: CSE 100 | H4: ECEN 101 | I4: Intro to ECEN/Computing | J4: 1 | L4: X | M4: ECEN 150 | N4: =M4 -> ECEN 150 | O4: Electric Circuit Analysis I | P4: 3
A5: X | B5: REL 225 | C5: Restoration Foundations | D5: 2 | F5: X | G5: CSE 110 | H5: CS 101 | I5: Intro to Programming | J5: 2 | L5: X | M5: ECEN 106/240 | N5: ECEN 160 | O5: Digital Systems w/ Lab | P5: 4
A6: T | B6: REL 250 | C6: Gospel of Jesus Christ | D6: 2 | F6: T | G6: CSE 111 | H6: CS 124 | I6: Intro to Software Dev (C) | J6: 3
A7: X | B7: REL 275 | C7: BOM Teachings & Doctrine | D7: 2 | F7: X | G7: CSE 121b | H7: CIT 160 | I7: Intro to Programming (JS) | J7: 3 | L7: X | M7: ECEN 260 | N7: ECEN 260 | O7: Microproc Based Design | P7: 3
A8: X | B8: REL 261 | C8: Intro to Family History | D8: 2 | F8: I | G8: CSE 150 | H8: NA | I8: Data Insight | J8: 2 | L8: X | M8: ECEN 324 | N8: ECEN 324 | O8: Computer Architecture | P8: 3
A9: X | B9: REL 301 | C9: Old Testament | D9: 2 | F9: X | G9: CSE 170 | H9: CIT 380 | I9: Tech Teamwork (PM) | J9: 3 | L9: X | M9: =N9 -> ECEN 340 | N9: ECEN 340 | O9: Digital Systems Design | P9: 3
A10: X | B10: REL 327 | C10: Pearl of Great Price | D10: 2 | F10: X | G10: CSE 210 | H10: CS 165 | I10: Obj-Ort Software Dev (C++) | J10: 3 | L10: X | M10: ECEN 350 | N10: =M10 -> ECEN 350 | O10: Devices and Circuits | P10: 3
A11: X | B11: GS 101 | C11: College Success | D11: 1 | F11: X | G11: CSE 212 | H11: CS 241 | I11: O-O Prog/Data Structs | J11: 4 | L11: X | M11: ECEN 361 | N11: ECEN 361 | O11: Embedded Systems | P11: 3
A12: X | B12: FAM 160 | C12: Family Relations | D12: 3 | F12: X | G12: CSE 280 | H12: CS 237 | I12: Discrete Math 1 | J12: 2 | L12: X | M12: ECEN 461 | N12: =M12 -> ECEN 461 | O12: Adv Embedded Systems | P12: 3
A13: X | B13: FAM 200 | C13: Prep for Marriage | D13: 2 | F13: X | G13: CSE 310 | H13: CS 246 | I13: Software Design & Dev | J13: 3 | L13: I | M13: ECEN 490 | N13: (CS 398) | O13: Special Topics | P13: 3
A14: T | B14: ART 101 | C14: Intro to Visual Art (APART) | D14: 3 | F14: X | G14: CSE 350 | H14: CS 335 | I14: Data Wrangling & Visual | J14: 3 | L14: I | M14: ECEN 499 | N14: ECEN 499 | O14: Senior Project | P14: 3
A15: I | B15: ENG 101 | C15: Writing Foundations | D15: 3
A16: X | B16: CS 308 | C16: Tech Com (Adv Writing) | D16: 3 | L16: X | M16: CIT 111/225 (CS 225) | O16: Database Design & Dev | P16: 6
A17: X | B17: MATH 112 | C17: Calc I | D17: 4 | L17: X | M17: CIT 171 | N17: CIT 270 | O17: System Security 1 | P17: 2
A18: T | B18: CHEM 101 | C18: Intro to Chem (APCHEM) | D18: 4 | L18: X | M18: WDD 130 | N18: WDD 100 | O18: Web Design & Dev | P18: 1
A19: X | B19: FDSCI 101 | C19: Sci Foundations | D19: 2

Sheet SE Completed
A1: Sem | B1: Code | D1: Name | E1: Crds | F1: Min | H1: BYUI
A2: Fall 2017 | B2: FDSCI | C2: 101 | D2: Science Foundations | E2: 2 | H2: ='SE Completed'!E8 -> 13
B3: ECEN | C3: 101 | D3: Intro to ECEN | E3: 1 | H3: ='SE Completed'!E15 -> 14
B4: ECEN | C4: 160 | D4: Fun of Digital Systems | E4: 3 | H4: ='SE Completed'!E22 -> 2
B5: =B4 -> ECEN | C5: 160L | D5: Digital Systems Lab | E5: 1 | H5: ='SE Completed'!E26 -> 14.5
B6: CS | C6: 241 | D6: O-O Prog/Data Structures | E6: 4 | H6: ='SE Completed'!E34 -> 12.5
B7: REL | C7: 275 | D7: Teachings of the BOM | E7: 2 | H7: ='SE Completed'!E41 -> 10
B8: Total | E8: =SUM(E2:E7) -> 13 | H8: ='SE Completed'!E44 -> 3
H9: ='SE Completed'!E51 -> 13
A10: Spring 2018 | B10: ENG | C10: 106 | D10: Basic Writing | E10: 3 | H10: ='SE Completed'!E57 -> 12
B11: CS | C11: 165 | D11: Obj-Ort Software Dev | E11: 3
B12: CS | C12: 225 | D12: Database Design & Dev | E12: 3 | H12: Done
B13: ECEN | C13: 260 | D13: Microproc Based Design | E13: 3 | H13: ='SE Completed'!H2+'SE Completed'!H3+'SE Completed'!H4+'SE Completed'!H5+'SE Completed'!H6+'SE Completed'!H7+'SE Completed'!H8+H9+H10 -> 94
B14: REL | C14: 327 | D14: Pearl of Great Price | E14: 2
B15: Total | E15: =SUM(E10:E14) -> 14 | H15: Total Done
A17: Sum 2018 | B17: REL | C17: 261 | D17: Intro to Family History | E17: 2 | H17: =H13+23 -> 117
B18: Total | E18: =SUM(E17) -> 2
A20: Fall 2018 | B20: MATH | C20: 109 | D20: PreCalculus | E20: 5
B21: CS | C21: 246 | D21: Software Design & Dev | E21: 3
B22: REL | C22: 301 | D22: Old Testament | E22: 2
B23: ECEN | C23: 361 | D23: Embedded Systems | E23: 3
B24: ENG | C24: 102R | D24: Reading Comp | E24: 0.5
B25: ESS | C25: 160 | D25: Swimming | E25: 1
B26: Total | E26: =SUM(E20:E25) -> 14.5
A28: Winter 2019 | B28: MATH | C28: 112 | D28: Calculus 1 | E28: 4
B29: REL | C29: 225 | D29: Restoration Foundations | E29: 2
B30: CS | C30: 237 | D30: Discrete Math 1 | E30: 2
B31: ECEN | C31: 324 | D31: Computer Architecture | E31: 3
B32: GS | C32: 103F | D32: Test Skills | E32: 0.5
B33: GS | C33: 106 | D33: College Success (GE 101) | E33: 1
B34: Total | E34: =SUM(E28:E33) -> 12.5
A36: Spring 2019 | B36: WDD | C36: 100 | D36: Intro to Web Dev | E36: 1
B37: ECEN | C37: 150 | D37: Electric Circuit Analysis 1 | E37: 3
B38: CS | C38: 308 | D38: Technical Communications | E38: 3
B39: MATH | C39: 330 | D39: Engineering Stats (W) | E39: 0
B40: ECEN | C40: 340 | D40: Digital Design | E40: 3
B41: Total | E41: =SUM(E36:E40) -> 10
A43: Sum 2019 | B43: FAM | C43: 160 | D43: Family Relations | E43: 3
B44: Total | E44: =SUM(E43) -> 3
A46: Fall 2019 | B46: FAM | C46: 200 | D46: Marriage Prep | E46: 2
...

Sheet Semesters
A1: Semester | B1: Course | C1: Crds | D1: Grade | E1: Pts | G1: Grade | H1: Pts | J1: Quality Pts
A2: Fall 2017 | B2: FDSCI 101 | C2: 2 | D2: B- | E2: =VLOOKUP(D2,$J$2:$K$15,2,FALSE)*C2 -> 5.4 | G2: P | H2: =VLOOKUP(G2,$J$2:$K$15,2,FALSE)*C2 -> 0 | J2: A | K2: 4
A3: Fall 2017 | B3: ECEN 101 | C3: 1 | D3: A | E3: =VLOOKUP(D3,$J$2:$K$15,2,FALSE)*C3 -> 4 | G3: A | H3: =VLOOKUP(G3,$J$2:$K$15,2,FALSE)*C3 -> 4 | J3: A- | K3: 3.7
A4: Fall 2017 | B4: ECEN 160 | C4: 3 | D4: A | E4: =VLOOKUP(D4,$J$2:$K$15,2,FALSE)*C4 -> 12 | G4: A | H4: =VLOOKUP(G4,$J$2:$K$15,2,FALSE)*C4 -> 12 | J4: B+ | K4: 3.4
A5: Fall 2017 | B5: ECEN 160L | C5: 1 | D5: A | E5: =VLOOKUP(D5,$J$2:$K$15,2,FALSE)*C5 -> 4 | G5: A | H5: =VLOOKUP(G5,$J$2:$K$15,2,FALSE)*C5 -> 4 | J5: B | K5: 3
A6: Fall 2017 | B6: CS 241 | C6: 4 | D6: A | E6: =VLOOKUP(D6,$J$2:$K$15,2,FALSE)*C6 -> 16 | G6: A | H6: =VLOOKUP(G6,$J$2:$K$15,2,FALSE)*C6 -> 16 | J6: B- | K6: 2.7
A7: Fall 2017 | B7: REL 275 | C7: 2 | D7: A | E7: =VLOOKUP(D7,$J$2:$K$15,2,FALSE)*C7 -> 8 | G7: P | H7: =VLOOKUP(G7,$J$2:$K$15,2,FALSE)*C7 -> 0 | J7: C+ | K7: 2.4
A8: Spring 2018 | B8: ENG 106 | C8: 3 | D8: A | E8: =VLOOKUP(D8,$J$2:$K$15,2,FALSE)*C8 -> 12 | G8: P | H8: =VLOOKUP(G8,$J$2:$K$15,2,FALSE)*C8 -> 0 | J8: C | K8: 2
A9: Spring 2018 | B9: CS 165 | C9: 3 | D9: A | E9: =VLOOKUP(D9,$J$2:$K$15,2,FALSE)*C9 -> 12 | G9: A | H9: =VLOOKUP(G9,$J$2:$K$15,2,FALSE)*C9 -> 12 | J9: C- | K9: 1.7
A10: Spring 2018 | B10: CS 225 | C10: 3 | D10: A | E10: =VLOOKUP(D10,$J$2:$K$15,2,FALSE)*C10 -> 12 | G10: A | H10: =VLOOKUP(G10,$J$2:$K$15,2,FALSE)*C10 -> 12 | J10: D+ | K10: 1.4
A11: Spring 2018 | B11: ECEN 260 | C11: 3 | D11: A | E11: =VLOOKUP(D11,$J$2:$K$15,2,FALSE)*C11 -> 12 | G11: A | H11: =VLOOKUP(G11,$J$2:$K$15,2,FALSE)*C11 -> 12 | J11: D | K11: 1
A12: Spring 2018 | B12: REL 327 | C12: 2 | D12: A | E12: =VLOOKUP(D12,$J$2:$K$15,2,FALSE)*C12 -> 8 | G12: P | H12: =VLOOKUP(G12,$J$2:$K$15,2,FALSE)*C12 -> 0 | J12: D- | K12: 0.7
A13: Summer 2018 | B13: REL 261 | C13: 2 | D13: A | E13: =VLOOKUP(D13,$J$2:$K$15,2,FALSE)*C13 -> 8 | G13: P | H13: =VLOOKUP(G13,$J$2:$K$15,2,FALSE)*C13 -> 0 | J13: F | K13: 0
... A15: Fall 2018 | B15: CS 246 | C15: 3 | D15: A- | E15: =VLOOKUP(D15,$J$2:$K$15,2,FALSE)*C15 -> 11.1 | G15: A- | H15: =VLOOKUP(G15,$J$2:$K$15,2,FALSE)*C15 -> 11.1 | J15: P | K15: 0
A16: Fall 2018 | B16: REL 301 | C16: 2 | D16: A | E16: =VLOOKUP(D16,$J$2:$K$15,2,FALSE)*C16 -> 8 | G16: P | H16: =VLOOKUP(G16,$J$2:$K$15,2,FALSE)*C16 -> 0
A17: Fall 2018 | B17: ECEN 361 | C17: 3 | D17: A- | E17: =VLOOKUP(D17,$J$2:$K$15,2,FALSE)*C17 -> 11.1 | G17: A- | H17: =VLOOKUP(G17,$J$2:$K$15,2,FALSE)*C17 -> 11.1
A18: Fall 2018 | B18: ENG 102 | C18: 0.5 | D18: A | E18: =VLOOKUP(D18,$J$2:$K$15,2,FALSE)*C18 -> 2 | G18: P | H18: =VLOOKUP(G18,$J$2:$K$15,2,FALSE)*C18 -> 0
A19: Fall 2018 | B19: ESS 160 | C19: 1 | D19: A | E19: =VLOOKUP(D19,$J$2:$K$15,2,FALSE)*C19 -> 4 | G19: P | H19: =VLOOKUP(G19,$J$2:$K$15,2,FALSE)*C19 -> 0
A20: Winter 2019 | B20: MATH 112 | C20: 4 | D20: A | E20: =VLOOKUP(D20,$J$2:$K$15,2,FALSE)*C20 -> 16 | G20: A | H20: =VLOOKUP(G20,$J$2:$K$15,2,FALSE)*C20 -> 16
A21: Winter 2019 | B21: REL 225 | C21: 2 | D21: A | E21: =VLOOKUP(D21,$J$2:$K$15,2,FALSE)*C21 -> 8 | G21: P | H21: =VLOOKUP(G21,$J$2:$K$15,2,FALSE)*C21 -> 0
A22: Winter 2019 | B22: CS 237 | C22: 2 | D22: A | E22: =VLOOKUP(D22,$J$2:$K$15,2,FALSE)*C22 -> 8 | G22: A | H22: =VLOOKUP(G22,$J$2:$K$15,2,FALSE)*C22 -> 8
A23: Winter 2019 | B23: ECEN 324 | C23: 3 | D23: C | E23: =VLOOKUP(D23,$J$2:$K$15,2,FALSE)*C23 -> 6 | G23: C | H23: =VLOOKUP(G23,$J$2:$K$15,2,FALSE)*C23 -> 6
A24: Winter 2019 | B24: GS 103F | C24: 0.5 | D24: A | E24: =VLOOKUP(D24,$J$2:$K$15,2,FALSE)*C24 -> 2 | G24: P | H24: =VLOOKUP(G24,$J$2:$K$15,2,FALSE)*C24 -> 0
A25: Winter 2019 | B25: GS 106 | C25: 1 | D25: A- | E25: =VLOOKUP(D25,$J$2:$K$15,2,FALSE)*C25 -> 3.7 | G25: P | H25: =VLOOKUP(G25,$J$2:$K$15,2,FALSE)*C25 -> 0
A26: Spring 2019 | B26: WDD 100 | C26: 1 | D26: A | E26: =VLOOKUP(D26,$J$2:$K$15,2,FALSE)*C26 -> 4 | G26: A | H26: =VLOOKUP(G26,$J$2:$K$15,2,FALSE)*C26 -> 4
A27: Spring 2019 | B27: ECEN 150 | C27: 3 | D27: C+ | E27: =VLOOKUP(D27,$J$2:$K$15,2,FALSE)*C27 -> 7.2 | G27: C+ | H27: =VLOOKUP(G27,$J$2:$K$15,2,FALSE)*C27 -> 7.2
... A43: Spring 2020 | B43: ECEN 499 | C43: 3 | D43: A | E43: =VLOOKUP(D43,$J$2:$K$15,2,FALSE)*C43 -> 12 | G43: A | H43: =VLOOKUP(G43,$J$2:$K$15,2,FALSE)*C43 -> 12
A44: Fall 2020 | B44: MATH 325 | C44: 3 | D44: B+ | E44: =VLOOKUP(D44,$J$2:$K$15,2,FALSE)*C44 -> 10.2 | G44: =D44 -> B+ | H44: =VLOOKUP(G44,$J$2:$K$15,2,FALSE)*C44 -> 10.2
A45: Fall 2020 | B45: CSE 450 | C45: 3 | D45: B+ | E45: =VLOOKUP(D45,$J$2:$K$15,2,FALSE)*C45 -> 10.2 | G45: =D45 -> B+ | H45: =VLOOKUP(G45,$J$2:$K$15,2,FALSE)*C45 -> 10.2

Sheet Copy of ECEN MSE
A1: ECEN MSE | K1: Courses to consider
A2: Requirements for Degree (Thesis Option) | F2: Requirements for Degree (Course Option) | K2: ECEN | L2: 523 | M2: Computer System Reliability | N2: 3
K3: ECEN | L3: 551 | M3: Intro to Digital VLSI Circuits | N3: 3
K4: ECEN | L4: 595 | M4: Patents and Intellectual Property | N4: 1
A5: 24 credit hours of graduate course work as specified by the advisory committee | F5: 30 credit hours of graduate course work as specified by the advisory committee | K5: ECEN | L5: 620 | M5: Adv Digital Systems | N5: 3
K6: ECEN | L6: 621 | M6: Computer Arithmetic | N6: 3
F7: ECEN | G7: 692 | H7: Professional Writing | I7: 2 | K7: ECEN | L7: 625 | M7: Compilation Strategies | N7: 3
A8: ECEN | B8: 692 | C8: Professional Writing | D8: 2 | F8: Study list: submitted during first semester of graduate study. | K8: ECEN | L8: 627 | M8: Adv Embedded Systems | N8: 3
A9: ECEN | B9: 699R | C9: Thesis | D9: 6 | K9: ECEN | L9: 629 | M9: Reconfigurable Computing Sys | N9: 3
A10: Study list: submitted during first semester of graduate study. | K10: CS | L10: 678 | M10: Adv Machine Learning Models | N10: 3
F11: Computer Engineering Core (6) | K11: TECH | L11: 601 | M11: R&D in Tech | N11: 3
A12: Final oral examination consisting of public presentation of original research described in thesis. | F12: ECEN | G12: 521 | H12: Intro to Algorithm Design | I12: 3 | K12: LING | L12: 581 | M12: Natural Language Processing | N12: 3
F13: CS | G13: 611 | H13: Computing Theoretical Fundamentals | I13: 3

Sheet ECEN PHD
A1: ECEN PHD | F1: Courses to consider (30)
A2: Required courses: 36 credit hours of graduate course work as specified by the advisory committee; and 20 from 692/799R | F2: ECEN | G2: 523 | H2: Computer System Reliability | I2: 3 | K2: TECH | L2: 601 | M2: R&D in Tech | N2: 3
F3: ECEN | G3: 526 | H3: Wireless Networking | I3: 3 | K3: MTHED | L3: 550 | M3: Problem Solving | N3: 3
F4: ECEN | G4: 551 | H4: Intro to Digital VLSI Circuits | I4: 3 | K4: LING | L4: 581 | M4: Natural Language Processing | N4: 3
A5: Study list: Submitted during the first semester of graduate study. Final oral examination consisting of public presentation of original research described in dissertation. | F5: ECEN | G5: 595 | H5: Patents and Intellectual Property | I5: 1 | K5: IT&C | L5: 529 | M5: Adv Networking | N5: 3
F6: ECEN | G6: 620 | H6: Adv Digital Systems | I6: 3 | K6: IT&C | L6: 544 | M6: System Admin | N6: 3
F7: ECEN | G7: 621 | H7: Computer Arithmetic | I7: 3 | K7: IT&C | L7: 548 | M7: Cyber-Physical Systems | N7: 3
F8: ECEN | G8: 625 | H8: Compilation Strategies | I8: 3 | K8: IT&C | L8: 567 | M8: CyberSecurity | N8: 3
A9: Competency exam: Completed in the third semester if entering with a BS degree | F9: ECEN | G9: 627 | H9: Adv Embedded Systems | I9: 3 | K9: IS | L9: 537 | M9: Data Structures and Algorithms | N9: 3
F10: ECEN | G10: 629 | H10: Reconfigurable Computing Sys | I10: 3 | K10: IS | L10: 542 | M10: Web Dev | N10: 3
A11: Qualifying exam: Completed by end of third year. | F11: ECEN | G11: 631 | H11: Robotic Vision | I11: 3
F12: ECEN | G12: 665 | H12: Wireless Communication | I12: 3
A13: Required ECEN Classes (20) | F13: ECEN | G13: 770 | H13: Info Theory | I13: 3
A14: ECEN | B14: 692 | C14: Professional Writing | D14: 2
A15: ECEN | B15: 799R | C15: Doctoral Dissertation | D15: 18
A16: Total | B16: =SUM(I2:I16) -> 34 | C16: Total | D16: =B16+D15+D14 -> 54
A17: Computer Engineering Core (6)
A18: ECEN | B18: 521 | C18: Intro to Algorithm Design | D18: 3
A19: CS | B19: 611 | C19: Computing Theoretical Fundamentals | D19: 3

Sheet Grad School
A1: http://ast.berkeley.edu/prospective-students/degree-requirements/
A2: https://grad.berkeley.edu/program/eecs/
A3: https://www.byu.edu/academics
A4: https://gradstudies.byu.edu/program/electrical-and-computer-engineering-ms
A5: https://www.uidaho.edu/admissions/graduate/graduate-programs
A6: https://www.uidaho.edu/admissions/graduate/graduate-programs/computer-engineering
A7: https://www.uidaho.edu/admissions/graduate/graduate-programs/computer-science
A8: https://www.boisestate.edu/academics-landing/
A9: https://www.boisestate.edu/graduatecollege/degree-programs/electrical-engineering/#degree-requirements
A10: https://www.boisestate.edu/graduatecollege/degree-programs/computer-science/#degree-requirements
A11: https://www.boisestate.edu/computing/
A12: https://catalog.usu.edu/preview_program.php?catoid=12&poid=9369&returnto=3827
... A18: https://www.colorado.edu/ecee/graduate-program/degrees-programs/master-engineering
