Workbook

Sheet Overview
A1: Semesters | B1: Term | F1: Cumulative | L1: =HYPERLINK("https://iplan.byui.edu/grad_planner/index.html#/myPlans","IPlan") -> IPlan
A2: Transfer/Vertical 23 crds | B2: Total Credits | C2: Total Points | D2: Term GPA | F2: Credits | G2: Retake Adj. | H2: Pts. | I2: GPA | J2: Total Credits
A3: Fall 2017 | B3: =SUMIF(Semesters!$A$2:$A$46,Overview!A3,Semesters!$C$2:$C$46) -> 13 | C3: =SUMIF(Semesters!$A$2:$A$46,Overview!A3,Semesters!$E$2:$E$46) -> 49.4 | D3: =C3/B3 -> 3.8 | F3: =B3 -> 13 | G3: 0 | H3: =C3 -> 49.4 | I3: =H3/(F3-G3) -> 3.8 | J3: =23 + F3 -> 36
A4: Spring 2018 | B4: =SUMIF(Semesters!$A$2:$A$46,Overview!A4,Semesters!$C$2:$C$46) -> 14 | C4: =SUMIF(Semesters!$A$2:$A$46,Overview!A4,Semesters!$E$2:$E$46) -> 56 | D4: =C4/B4 -> 4 | F4: =B4+F3-G3 -> 27 | G4: 0 | H4: =H3+C4 -> 105.4 | I4: =H4/(F4-G4) -> 3.9037037 | J4: =F4+23 -> 50
A5: Summer 2018 | B5: =SUMIF(Semesters!$A$2:$A$46,Overview!A5,Semesters!$C$2:$C$46) -> 2 | C5: =SUMIF(Semesters!$A$2:$A$46,Overview!A5,Semesters!$E$2:$E$46) -> 8 | D5: =C5/B5 -> 4 | F5: =B5+F4-G4 -> 29 | G5: 0 | H5: =H4+C5 -> 113.4 | I5: =H5/(F5-G5) -> 3.9103448 | J5: =F5+23 -> 52
A6: Fall 2018 | B6: =SUMIF(Semesters!$A$2:$A$46,Overview!A6,Semesters!$C$2:$C$46) -> 14.5 | C6: =SUMIF(Semesters!$A$2:$A$46,Overview!A6,Semesters!$E$2:$E$46) -> 56.2 | D6: =C6/B6 -> 3.8758621 | F6: =B6+F5-G5 -> 43.5 | G6: 0 | H6: =H5+C6 -> 169.6 | I6: =H6/(F6-G6) -> 3.8988506 | J6: =F6+23 -> 66.5
A7: Winter 2019 | B7: =SUMIF(Semesters!$A$2:$A$46,Overview!A7,Semesters!$C$2:$C$46) -> 12.5 | C7: =SUMIF(Semesters!$A$2:$A$46,Overview!A7,Semesters!$E$2:$E$46) -> 43.7 | D7: =C7/B7 -> 3.496 | F7: =B7+F6-G6 -> 56 | G7: 0 | H7: =H6+C7 -> 213.3 | I7: =H7/(F7-G7) -> 3.8089286 | J7: =F7+23 -> 79
A8: Spring 2019 | B8: =SUMIF(Semesters!$A$2:$A$46,Overview!A8,Semesters!$C$2:$C$46) -> 10 | C8: =SUMIF(Semesters!$A$2:$A$46,Overview!A8,Semesters!$E$2:$E$46) -> 35.2 | D8: =C8/B8 -> 3.52 | F8: =B8+F7-G7 -> 66 | G8: 0 | H8: =H7+C8 -> 248.5 | I8: =H8/(F8-G8) -> 3.7651515 | J8: =F8+23 -> 89
A9: Summer 2019 | B9: =SUMIF(Semesters!$A$2:$A$46,Overview!A9,Semesters!$C$2:$C$46) -> 3 | C9: =SUMIF(Semesters!$A$2:$A$46,Overview!A9,Semesters!$E$2:$E$46) -> 10.2 | D9: =C9/B9 -> 3.4 | F9: =B9+F8-G8 -> 69 | G9: 0 | H9: =H8+C9 -> 258.7 | I9: =H9/(F9-G9) -> 3.7492754 | J9: =F9+23 -> 92
A10: Fall 2019 | B10: =SUMIF(Semesters!$A$2:$A$46,Overview!A10,Semesters!$C$2:$C$46) -> 13 | C10: =SUMIF(Semesters!$A$2:$A$46,Overview!A10,Semesters!$E$2:$E$46) -> 37 | D10: =C10/B10 -> 2.8461538 | F10: =B10+F9-G9 -> 82 | G10: 0 | H10: =H9+C10 -> 295.7 | I10: =H10/(F10-G10) -> 3.6060976 | J10: =F10+23 -> 105
A11: Winter 2020 | B11: =SUMIF(Semesters!$A$2:$A$46,Overview!A11,Semesters!$C$2:$C$46) -> 12 | C11: =SUMIF(Semesters!$A$2:$A$46,Overview!A11,Semesters!$E$2:$E$46) -> 45.3 | D11: =C11/B11 -> 3.775 | F11: =B11+F10-G10 -> 94 | G11: 0 | H11: =H10+C11 -> 341 | I11: =H11/(F11-G11) -> 3.6276596 | J11: =F11+23 -> 117
A12: Spring 2020 | B12: =SUMIF(Semesters!$A$2:$A$46,Overview!A12,Semesters!$C$2:$C$46) -> 8 | C12: =SUMIF(Semesters!$A$2:$A$46,Overview!A12,Semesters!$E$2:$E$46) -> #N/A | D12: =C12/B12 -> #N/A | F12: =B12+F11-G11 -> 102 | G12: 0 | H12: =H11+C12 -> #N/A | I12: =H12/(F12-G12) -> #N/A | J12: =F12+23 -> 125

Sheet Core
A1: Software Engineering (BS)
A2: Academic Core | D2: =SUM(D4:D19) -> 39 | F2: Major Core | P2: =SUM(J4:J15)+SUM(P4:P18) -> 69
A3: P | B3: Code | C3: Name | D3: Crds | F3: P | G3: New | H3: Old | I3: Name | J3: Crds | L3: P | M3: New | N3: Old | O3: Name | P3: Crds
A4: X | B4: REL 200 | C4: The Eternal Family | D4: 2 | F4: X | G4: CSE 100 | H4: ECEN 101 | I4: Intro to ECEN/Computing | J4: 1 | L4: X | M4: ECEN 150 | N4: =M4 -> ECEN 150 | O4: Electric Circuit Analysis I | P4: 3
A5: X | B5: REL 225 | C5: Restoration Foundations | D5: 2 | F5: X | G5: CSE 110 | H5: CS 101 | I5: Intro to Programming | J5: 2 | L5: X | M5: ECEN 106/240 | N5: ECEN 160 | O5: Digital Systems w/ Lab | P5: 4
A6: T | B6: REL 250 | C6: Gospel of Jesus Christ | D6: 2 | F6: T | G6: CSE 111 | H6: CS 124 | I6: Intro to Software Dev (C) | J6: 3
A7: X | B7: REL 275 | C7: BOM Teachings & Doctrine | D7: 2 | F7: X | G7: CSE 121b | H7: CIT 160 | I7: Intro to Programming (JS) | J7: 3 | L7: X | M7: ECEN 260 | N7: ECEN 260 | O7: Microproc Based Design | P7: 3
A8: X | B8: REL 261 | C8: Intro to Family History | D8: 2 | F8: I | G8: CSE 150 | H8: NA | I8: Data Insight | J8: 2 | L8: X | M8: ECEN 324 | N8: ECEN 324 | O8: Computer Architecture | P8: 3
A9: X | B9: REL 301 | C9: Old Testament | D9: 2 | F9: X | G9: CSE 170 | H9: CIT 380 | I9: Tech Teamwork (PM) | J9: 3 | L9: X | M9: =N9 -> ECEN 340 | N9: ECEN 340 | O9: Digital Systems Design | P9: 3
A10: X | B10: REL 327 | C10: Pearl of Great Price | D10: 2 | F10: X | G10: CSE 210 | H10: CS 165 | I10: Obj-Ort Software Dev (C++) | J10: 3 | L10: X | M10: ECEN 350 | N10: =M10 -> ECEN 350 | O10: Devices and Circuits | P10: 3
A11: X | B11: GS 101 | C11: College Success | D11: 1 | F11: X | G11: CSE 212 | H11: CS 241 | I11: O-O Prog/Data Structs | J11: 4 | L11: X | M11: ECEN 361 | N11: ECEN 361 | O11: Embedded Systems | P11: 3
A12: X | B12: FAM 160 | C12: Family Relations | D12: 3 | F12: X | G12: CSE 280 | H12: CS 237 | I12: Discrete Math 1 | J12: 2 | L12: X | M12: ECEN 461 | N12: =M12 -> ECEN 461 | O12: Adv Embedded Systems | P12: 3
A13: X | B13: FAM 200 | C13: Prep for Marriage | D13: 2 | F13: X | G13: CSE 310 | H13: CS 246 | I13: Software Design & Dev | J13: 3 | L13: I | M13: ECEN 490 | N13: (CS 398) | O13: Special Topics | P13: 3
A14: T | B14: ART 101 | C14: Intro to Visual Art (APART) | D14: 3 | F14: X | G14: CSE 350 | H14: CS 335 | I14: Data Wrangling & Visual | J14: 3 | L14: I | M14: ECEN 499 | N14: ECEN 499 | O14: Senior Project | P14: 3
A15: I | B15: ENG 101 | C15: Writing Foundations | D15: 3
A16: X | B16: CS 308 | C16: Tech Com (Adv Writing) | D16: 3 | L16: X | M16: CIT 111/225 (CS 225) | O16: Database Design & Dev | P16: 6
A17: X | B17: MATH 112 | C17: Calc I | D17: 4 | L17: X | M17: CIT 171 | N17: CIT 270 | O17: System Security 1 | P17: 2
A18: T | B18: CHEM 101 | C18: Intro to Chem (APCHEM) | D18: 4 | L18: X | M18: WDD 130 | N18: WDD 100 | O18: Web Design & Dev | P18: 1
A19: X | B19: FDSCI 101 | C19: Sci Foundations | D19: 2

Sheet SE Completed
A1: Sem | B1: Code | D1: Name | E1: Crds | F1: Min | H1: BYUI
A2: Fall 2017 | B2: FDSCI | C2: 101 | D2: Science Foundations | E2: 2 | H2: ='SE Completed'!E8 -> 13
B3: ECEN | C3: 101 | D3: Intro to ECEN | E3: 1 | H3: ='SE Completed'!E15 -> 14
B4: ECEN | C4: 160 | D4: Fun of Digital Systems | E4: 3 | H4: ='SE Completed'!E22 -> 2
B5: =B4 -> ECEN | C5: 160L | D5: Digital Systems Lab | E5: 1 | H5: ='SE Completed'!E26 -> 14.5
B6: CS | C6: 241 | D6: O-O Prog/Data Structures | E6: 4 | H6: ='SE Completed'!E34 -> 12.5
B7: REL | C7: 275 | D7: Teachings of the BOM | E7: 2 | H7: ='SE Completed'!E41 -> 10
B8: Total | E8: =SUM(E2:E7) -> 13 | H8: ='SE Completed'!E44 -> 3
H9: ='SE Completed'!E51 -> 13
A10: Spring 2018 | B10: ENG | C10: 106 | D10: Basic Writing | E10: 3 | H10: ='SE Completed'!E57 -> 12
B11: CS | C11: 165 | D11: Obj-Ort Software Dev | E11: 3
B12: CS | C12: 225 | D12: Database Design & Dev | E12: 3 | H12: Done
B13: ECEN | C13: 260 | D13: Microproc Based Design | E13: 3 | H13: ='SE Completed'!H2+'SE Completed'!H3+'SE Completed'!H4+'SE Completed'!H5+'SE Completed'!H6+'SE Completed'!H7+'SE Completed'!H8+H9+H10 -> 94
B14: REL | C14: 327 | D14: Pearl of Great Price | E14: 2
B15: Total | E15: =SUM(E10:E14) -> 14 | H15: Total Done
A17: Sum 2018 | B17: REL | C17: 261 | D17: Intro to Family History | E17: 2 | H17: =H13+23 -> 117
B18: Total | E18: =SUM(E17) -> 2
A20: Fall 2018 | B20: MATH | C20: 109 | D20: PreCalculus | E20: 5
B21: CS | C21: 246 | D21: Software Design & Dev | E21: 3
B22: REL | C22: 301 | D22: Old Testament | E22: 2
B23: ECEN | C23: 361 | D23: Embedded Systems | E23: 3
B24: ENG | C24: 102R | D24: Reading Comp | E24: 0.5
B25: ESS | C25: 160 | D25: Swimming | E25: 1
B26: Total | E26: =SUM(E20:E25) -> 14.5
A28: Winter 2019 | B28: MATH | C28: 112 | D28: Calculus 1 | E28: 4
B29: REL | C29: 225 | D29: Restoration Foundations | E29: 2
B30: CS | C30: 237 | D30: Discrete Math 1 | E30: 2
B31: ECEN | C31: 324 | D31: Computer Architecture | E31: 3
B32: GS | C32: 103F | D32: Test Skills | E32: 0.5
B33: GS | C33: 106 | D33: College Success (GE 101) | E33: 1
B34: Total | E34: =SUM(E28:E33) -> 12.5
A36: Spring 2019 | B36: WDD | C36: 100 | D36: Intro to Web Dev | E36: 1
B37: ECEN | C37: 150 | D37: Electric Circuit Analysis 1 | E37: 3
B38: CS | C38: 308 | D38: Technical Communications | E38: 3
B39: MATH | C39: 330 | D39: Engineering Stats (W) | E39: 0
B40: ECEN | C40: 340 | D40: Digital Design | E40: 3
B41: Total | E41: =SUM(E36:E40) -> 10
A43: Sum 2019 | B43: FAM | C43: 160 | D43: Family Relations | E43: 3
B44: Total | E44: =SUM(E43) -> 3
A46: Fall 2019 | B46: FAM | C46: 200 | D46: Marriage Prep | E46: 2
...

Sheet Semesters
A1: Semester | B1: Course | C1: Crds | D1: Grade | E1: Pts | G1: Quality Pts
A2: Fall 2017 | B2: FDSCI 101 | C2: 2 | D2: B- | E2: =VLOOKUP(D2,$G$2:$H$15,2,FALSE)*C2 -> 5.4 | G2: A | H2: 4
A3: Fall 2017 | B3: ECEN 101 | C3: 1 | D3: A | E3: =VLOOKUP(D3,$G$2:$H$15,2,FALSE)*C3 -> 4 | G3: A- | H3: 3.7
A4: Fall 2017 | B4: ECEN 160 | C4: 3 | D4: A | E4: =VLOOKUP(D4,$G$2:$H$15,2,FALSE)*C4 -> 12 | G4: B+ | H4: 3.4
A5: Fall 2017 | B5: ECEN 160L | C5: 1 | D5: A | E5: =VLOOKUP(D5,$G$2:$H$15,2,FALSE)*C5 -> 4 | G5: B | H5: 3
A6: Fall 2017 | B6: CS 241 | C6: 4 | D6: A | E6: =VLOOKUP(D6,$G$2:$H$15,2,FALSE)*C6 -> 16 | G6: B- | H6: 2.7
A7: Fall 2017 | B7: REL 275 | C7: 2 | D7: A | E7: =VLOOKUP(D7,$G$2:$H$15,2,FALSE)*C7 -> 8 | G7: C+ | H7: 2.4
A8: Spring 2018 | B8: ENG 106 | C8: 3 | D8: A | E8: =VLOOKUP(D8,$G$2:$H$15,2,FALSE)*C8 -> 12 | G8: C | H8: 2
A9: Spring 2018 | B9: CS 165 | C9: 3 | D9: A | E9: =VLOOKUP(D9,$G$2:$H$15,2,FALSE)*C9 -> 12 | G9: C- | H9: 1.7
A10: Spring 2018 | B10: CS 225 | C10: 3 | D10: A | E10: =VLOOKUP(D10,$G$2:$H$15,2,FALSE)*C10 -> 12 | G10: D+ | H10: 1.4
A11: Spring 2018 | B11: ECEN 260 | C11: 3 | D11: A | E11: =VLOOKUP(D11,$G$2:$H$15,2,FALSE)*C11 -> 12 | G11: D | H11: 1
A12: Spring 2018 | B12: REL 327 | C12: 2 | D12: A | E12: =VLOOKUP(D12,$G$2:$H$15,2,FALSE)*C12 -> 8 | G12: D- | H12: 0.7
A13: Summer 2018 | B13: REL 261 | C13: 2 | D13: A | E13: =VLOOKUP(D13,$G$2:$H$15,2,FALSE)*C13 -> 8 | G13: F | H13: 0
... A15: Fall 2018 | B15: CS 246 | C15: 3 | D15: A- | E15: =VLOOKUP(D15,$G$2:$H$15,2,FALSE)*C15 -> 11.1 | G15: P | H15: 0
A16: Fall 2018 | B16: REL 301 | C16: 2 | D16: A | E16: =VLOOKUP(D16,$G$2:$H$15,2,FALSE)*C16 -> 8
A17: Fall 2018 | B17: ECEN 361 | C17: 3 | D17: A- | E17: =VLOOKUP(D17,$G$2:$H$15,2,FALSE)*C17 -> 11.1
A18: Fall 2018 | B18: ENG 102 | C18: 0.5 | D18: A | E18: =VLOOKUP(D18,$G$2:$H$15,2,FALSE)*C18 -> 2
A19: Fall 2018 | B19: ESS 160 | C19: 1 | D19: A | E19: =VLOOKUP(D19,$G$2:$H$15,2,FALSE)*C19 -> 4
A20: Winter 2019 | B20: MATH 112 | C20: 4 | D20: A | E20: =VLOOKUP(D20,$G$2:$H$15,2,FALSE)*C20 -> 16
A21: Winter 2019 | B21: REL 225 | C21: 2 | D21: A | E21: =VLOOKUP(D21,$G$2:$H$15,2,FALSE)*C21 -> 8
A22: Winter 2019 | B22: CS 237 | C22: 2 | D22: A | E22: =VLOOKUP(D22,$G$2:$H$15,2,FALSE)*C22 -> 8
A23: Winter 2019 | B23: ECEN 324 | C23: 3 | D23: C | E23: =VLOOKUP(D23,$G$2:$H$15,2,FALSE)*C23 -> 6
A24: Winter 2019 | B24: GS 103F | C24: 0.5 | D24: A | E24: =VLOOKUP(D24,$G$2:$H$15,2,FALSE)*C24 -> 2
A25: Winter 2019 | B25: GS 106 | C25: 1 | D25: A- | E25: =VLOOKUP(D25,$G$2:$H$15,2,FALSE)*C25 -> 3.7
A26: Spring 2019 | B26: WDD 100 | C26: 1 | D26: A | E26: =VLOOKUP(D26,$G$2:$H$15,2,FALSE)*C26 -> 4
A27: Spring 2019 | B27: ECEN 150 | C27: 3 | D27: C+ | E27: =VLOOKUP(D27,$G$2:$H$15,2,FALSE)*C27 -> 7.2
... A40: Winter 2020 | B40: ECEN 461 | C40: 3 | D40: A | E40: =VLOOKUP(D40,$G$2:$H$15,2,FALSE)*C40 -> 12
A41: Spring 2020 | B41: CSE 150 | C41: 2 | E41: =VLOOKUP(D41,$G$2:$H$15,2,FALSE)*C41 -> #N/A
A42: Spring 2020 | B42: ECEN 490 | C42: 3 | E42: =VLOOKUP(D42,$G$2:$H$15,2,FALSE)*C42 -> #N/A
A43: Spring 2020 | B43: ECEN 499 | C43: 3 | E43: =VLOOKUP(D43,$G$2:$H$15,2,FALSE)*C43 -> #N/A

Sheet Copy of ECEN MSE
A1: ECEN MSE | K1: Courses to consider
A2: Requirements for Degree (Thesis Option) | F2: Requirements for Degree (Course Option) | K2: ECEN | L2: 523 | M2: Computer System Reliability | N2: 3
K3: ECEN | L3: 551 | M3: Intro to Digital VLSI Circuits | N3: 3
K4: ECEN | L4: 595 | M4: Patents and Intellectual Property | N4: 1
A5: 24 credit hours of graduate course work as specified by the advisory committee | F5: 30 credit hours of graduate course work as specified by the advisory committee | K5: ECEN | L5: 620 | M5: Adv Digital Systems | N5: 3
K6: ECEN | L6: 621 | M6: Computer Arithmetic | N6: 3
F7: ECEN | G7: 692 | H7: Professional Writing | I7: 2 | K7: ECEN | L7: 625 | M7: Compilation Strategies | N7: 3
A8: ECEN | B8: 692 | C8: Professional Writing | D8: 2 | F8: Study list: submitted during first semester of graduate study. | K8: ECEN | L8: 627 | M8: Adv Embedded Systems | N8: 3
A9: ECEN | B9: 699R | C9: Thesis | D9: 6 | K9: ECEN | L9: 629 | M9: Reconfigurable Computing Sys | N9: 3
A10: Study list: submitted during first semester of graduate study. | K10: CS | L10: 678 | M10: Adv Machine Learning Models | N10: 3
F11: Computer Engineering Core (6) | K11: TECH | L11: 601 | M11: R&D in Tech | N11: 3
A12: Final oral examination consisting of public presentation of original research described in thesis. | F12: ECEN | G12: 521 | H12: Intro to Algorithm Design | I12: 3 | K12: LING | L12: 581 | M12: Natural Language Processing | N12: 3
F13: CS | G13: 611 | H13: Computing Theoretical Fundamentals | I13: 3

Sheet ECEN PHD
A1: ECEN PHD | F1: Courses to consider (30)
A2: Required courses: 36 credit hours of graduate course work as specified by the advisory committee; and 20 from 692/799R | F2: ECEN | G2: 523 | H2: Computer System Reliability | I2: 3 | K2: TECH | L2: 601 | M2: R&D in Tech | N2: 3
F3: ECEN | G3: 526 | H3: Wireless Networking | I3: 3 | K3: MTHED | L3: 550 | M3: Problem Solving | N3: 3
F4: ECEN | G4: 551 | H4: Intro to Digital VLSI Circuits | I4: 3 | K4: LING | L4: 581 | M4: Natural Language Processing | N4: 3
A5: Study list: Submitted during the first semester of graduate study. Final oral examination consisting of public presentation of original research described in dissertation. | F5: ECEN | G5: 595 | H5: Patents and Intellectual Property | I5: 1 | K5: IT&C | L5: 529 | M5: Adv Networking | N5: 3
F6: ECEN | G6: 620 | H6: Adv Digital Systems | I6: 3 | K6: IT&C | L6: 544 | M6: System Admin | N6: 3
F7: ECEN | G7: 621 | H7: Computer Arithmetic | I7: 3 | K7: IT&C | L7: 548 | M7: Cyber-Physical Systems | N7: 3
F8: ECEN | G8: 625 | H8: Compilation Strategies | I8: 3 | K8: IT&C | L8: 567 | M8: CyberSecurity | N8: 3
A9: Competency exam: Completed in the third semester if entering with a BS degree | F9: ECEN | G9: 627 | H9: Adv Embedded Systems | I9: 3 | K9: IS | L9: 537 | M9: Data Structures and Algorithms | N9: 3
F10: ECEN | G10: 629 | H10: Reconfigurable Computing Sys | I10: 3 | K10: IS | L10: 542 | M10: Web Dev | N10: 3
A11: Qualifying exam: Completed by end of third year. | F11: ECEN | G11: 631 | H11: Robotic Vision | I11: 3
F12: ECEN | G12: 665 | H12: Wireless Communication | I12: 3
A13: Required ECEN Classes (20) | F13: ECEN | G13: 770 | H13: Info Theory | I13: 3
A14: ECEN | B14: 692 | C14: Professional Writing | D14: 2
A15: ECEN | B15: 799R | C15: Doctoral Dissertation | D15: 18
A16: Total | B16: =SUM(I2:I16) -> 34 | C16: Total | D16: =B16+D15+D14 -> 54
A17: Computer Engineering Core (6)
A18: ECEN | B18: 521 | C18: Intro to Algorithm Design | D18: 3
A19: CS | B19: 611 | C19: Computing Theoretical Fundamentals | D19: 3

Sheet ECEN MSE
A1: ECEN MSE | K1: Courses to consider | N1: =SUM(N2:N10) -> 24
A2: Requirements for Degree | K2: ECEN | L2: 523 | M2: Computer System Reliability | N2: 3
A3: (Thesis Option) MS | F3: (Course Option) ME | K3: ECEN | L3: 551 | M3: Intro to Digital VLSI Circuits | N3: 3
K4: ECEN | L4: 620 | M4: Adv Digital Systems | N4: 3
A5: 24 credit hours of graduate course work as specified by the advisory committee | F5: 30 credit hours of graduate course work as specified by the advisory committee | K5: ECEN | L5: 621 | M5: Computer Arithmetic | N5: 3
K6: ECEN | L6: 625 | M6: Compilation Strategies | N6: 3
F7: ECEN | G7: 692 | H7: Professional Writing | I7: 2 | K7: ECEN | L7: 627 | M7: Adv Embedded Systems | N7: 3
A8: ECEN | B8: 692 | C8: Professional Writing | D8: 2 | F8: Study list: submitted during first semester of graduate study. | K8: ECEN | L8: 629 | M8: Reconfigurable Computing Sys | N8: 3
A9: ECEN | B9: 699R | C9: Thesis | D9: 6
A10: Study list: submitted during first semester of graduate study. | K10: TECH | L10: 601 | M10: R&D in Tech | N10: 3
F11: Computer Engineering Core | I11: =SUM(I12:I14) -> 6
A12: Final oral examination consisting of public presentation of original research described in thesis. | F12: ECEN | G12: 521 | H12: Intro to Algorithm Design | I12: 3 | N12: =SUM(N2:N10) -> 24
F13: CS | G13: 611 | H13: Computing Theoretical Fundamentals | I13: 3

Sheet Grad School
A1: http://ast.berkeley.edu/prospective-students/degree-requirements/
A2: https://grad.berkeley.edu/program/eecs/
A3: https://www.byu.edu/academics
A4: https://gradstudies.byu.edu/program/electrical-and-computer-engineering-ms
A5: https://www.uidaho.edu/admissions/graduate/graduate-programs
A6: https://www.uidaho.edu/admissions/graduate/graduate-programs/computer-engineering
A7: https://www.uidaho.edu/admissions/graduate/graduate-programs/computer-science
A8: https://www.boisestate.edu/academics-landing/
A9: https://www.boisestate.edu/graduatecollege/degree-programs/electrical-engineering/#degree-requirements
A10: https://www.boisestate.edu/graduatecollege/degree-programs/computer-science/#degree-requirements
A11: https://www.boisestate.edu/computing/
A12: https://catalog.usu.edu/preview_program.php?catoid=12&poid=9369&returnto=3827
... A18: https://www.colorado.edu/ecee/graduate-program/degrees-programs/master-engineering
